Workbook

Sheet 00_Data_Dictionary
A1: Table | B1: Column | C1: Meaning | D1: Example / Values
A2: ATMs | B2: ATM_ID | C2: Unique ATM identifier | D2: ATM001
A3: ATMs | B3: City | C3: City where ATM is located | D3: Nagpur
A4: ATMs | B4: Area_Type | C4: Type of location | D4: Urban / Semi-Urban / Rural
A5: ATMs | B5: ATM_Type | C5: ATM installation/location type | D5: On-Site / Off-Site / Mall / Transit
A6: ATMs | B6: Installation_Date | C6: ATM installation date | D6: 2023-05-18
A7: Transactions | B7: Transaction_ID | C7: Unique transaction identifier | D7: TXN000001
A8: Transactions | B8: ATM_ID | C8: ATM used for transaction | D8: ATM001
A9: Transactions | B9: Transaction_Date | C9: Date of transaction | D9: 2025-04-12
A10: Transactions | B10: Transaction_Time | C10: Time of transaction | D10: 18:45:10
A11: Transactions | B11: Transaction_Type | C11: Type of ATM transaction | D11: Withdrawal
A12: Transactions | B12: Amount | C12: Transaction amount | D12: 2000
... A23: Maintenance | B23: Downtime_Hours | C23: ATM downtime duration | D23: 4.5

Sheet 01_Raw_ATMs
A1: ATM_ID | B1: City | C1: Area_Type | D1: ATM_Type | E1: Installation_Date
A2: ATM001 | B2: Pune | C2: Urban | D2: Mall | E2: 44698
A3: ATM002 | B3: Nashik | C3: Urban | D3: On-Site | E3: 45582
A4: ATM003 | B4: Pune | C4: Semi-Urban | D4: On-Site | E4: 44258
A5: ATM004 | B5: Pune | C5: Urban | D5: On-Site | E5: 45346
A6: ATM005 | B6: Nashik | C6: Semi-Urban | D6: Transit | E6: 44648
A7: ATM006 | B7: Hyderabad | C7: Semi-Urban | D7: On-Site | E7: 45751
A8: ATM007 | B8: Mumbai | C8: Semi-Urban | D8: Mall | E8: 44766
A9: ATM008 | B9: Mumbai | C9: Urban | D9: Mall | E9: 44406
A10: ATM009 | B10: Pune | C10: Urban | D10: Mall | E10: 44901
A11: ATM010 | B11: Aurangabad | C11: Semi-Urban | D11: Transit | E11: 45295
A12: ATM011 | B12: Pune | C12: Rural | D12: Transit | E12: 44358
A13: ATM012 | B13: Aurangabad | C13: Semi-Urban | D13: Mall | E13: 45379
... A101: ATM100 | B101: Aurangabad | C101: Urban | D101: Transit | E101: 44904

Sheet 02_Raw_Transactions
A1: Transaction_ID | B1: ATM_ID | C1: Transaction_Date | D1: Transaction_Time | E1: Transaction_Type | F1: Amount | G1: Status | H1: Failure_Reason | I1: Duplicate_Check | J1: Missing_Reason_Check | K1: Clean_Status | L1: Clean_Transaction_Type | M1: Amount_Check | N1: Date_Check | O1: ATM_Master_Check | P1: Missing_ATM_ID
A2: TXN000001 | B2: ATM094 | C2: 45979 | D2: 0.60563657 | E2: Withdrawal | F2: 8000 | G2: Successful | I2: =COUNTIF($A:$A,A2) -> 1 | J2: =IF(AND(TRIM(G2)="Failed",H2=""),"Problem","OK") -> OK | K2: =PROPER(TRIM(G2)) -> Successful | L2: =PROPER(TRIM(E2)) -> Withdrawal | M2: =IF(OR(E2="Withdrawal",E2="Cash Deposit"),IF(F2>0,"OK","Problem"),IF(F2=0,"OK","Problem")) -> OK | N2: =IF(AND(C2>=DATE(2025,1,1),C2<=DATE(2026,6,30)),"OK","Problem") -> OK | O2: =_xlfn.XLOOKUP(B2,'01_Raw_ATMs'!A:A,'01_Raw_ATMs'!A:A,"Not Found") -> ATM094 | P2: =IF(B2="","Missing ATM_ID","Valid") -> Valid
A3: TXN000002 | B3: ATM006 | C3: 46104 | D3: 0.0415625 | E3: Withdrawal | F3: 10000 | G3: Successful | I3: =COUNTIF($A:$A,A3) -> 1 | J3: =IF(AND(TRIM(G3)="Failed",H3=""),"Problem","OK") -> OK | K3: =PROPER(TRIM(G3)) -> Successful | L3: =PROPER(TRIM(E3)) -> Withdrawal | M3: =IF(OR(E3="Withdrawal",E3="Cash Deposit"),IF(F3>0,"OK","Problem"),IF(F3=0,"OK","Problem")) -> OK | N3: =IF(AND(C3>=DATE(2025,1,1),C3<=DATE(2026,6,30)),"OK","Problem") -> OK | O3: =_xlfn.XLOOKUP(B3,'01_Raw_ATMs'!A:A,'01_Raw_ATMs'!A:A,"Not Found") -> ATM006 | P3: =IF(B3="","Missing ATM_ID","Valid") -> Valid | R3: =ROWS(A2:A10001) -> 10000
A4: TXN000003 | B4: ATM056 | C4: 45729 | D4: 0.9571875 | E4: Withdrawal | F4: 10000 | G4: Successful | I4: =COUNTIF($A:$A,A4) -> 1 | J4: =IF(AND(TRIM(G4)="Failed",H4=""),"Problem","OK") -> OK | K4: =PROPER(TRIM(G4)) -> Successful | L4: =PROPER(TRIM(E4)) -> Withdrawal | M4: =IF(OR(E4="Withdrawal",E4="Cash Deposit"),IF(F4>0,"OK","Problem"),IF(F4=0,"OK","Problem")) -> OK | N4: =IF(AND(C4>=DATE(2025,1,1),C4<=DATE(2026,6,30)),"OK","Problem") -> OK | O4: =_xlfn.XLOOKUP(B4,'01_Raw_ATMs'!A:A,'01_Raw_ATMs'!A:A,"Not Found") -> ATM056 | P4: =IF(B4="","Missing ATM_ID","Valid") -> Valid | R4: =COLUMNS(A1:H1) -> 8
A5: TXN000004 | B5: ATM093 | C5: 45965 | D5: 0.69613426 | E5: Withdrawal | F5: 2500 | G5: Successful | I5: =COUNTIF($A:$A,A5) -> 1 | J5: =IF(AND(TRIM(G5)="Failed",H5=""),"Problem","OK") -> OK | K5: =PROPER(TRIM(G5)) -> Successful | L5: =PROPER(TRIM(E5)) -> Withdrawal | M5: =IF(OR(E5="Withdrawal",E5="Cash Deposit"),IF(F5>0,"OK","Problem"),IF(F5=0,"OK","Problem")) -> OK | N5: =IF(AND(C5>=DATE(2025,1,1),C5<=DATE(2026,6,30)),"OK","Problem") -> OK | O5: =_xlfn.XLOOKUP(B5,'01_Raw_ATMs'!A:A,'01_Raw_ATMs'!A:A,"Not Found") -> ATM093 | P5: =IF(B5="","Missing ATM_ID","Valid") -> Valid | R5: =COUNTIF(I1:I10001,2) -> 10
A6: TXN000005 | B6: ATM025 | C6: 46088 | D6: 0.76716435 | E6: Balance Inquiry | F6: 0 | G6: Successful | I6: =COUNTIF($A:$A,A6) -> 1 | J6: =IF(AND(TRIM(G6)="Failed",H6=""),"Problem","OK") -> OK | K6: =PROPER(TRIM(G6)) -> Successful | L6: =PROPER(TRIM(E6)) -> Balance Inquiry | M6: =IF(OR(E6="Withdrawal",E6="Cash Deposit"),IF(F6>0,"OK","Problem"),IF(F6=0,"OK","Problem")) -> OK | N6: =IF(AND(C6>=DATE(2025,1,1),C6<=DATE(2026,6,30)),"OK","Problem") -> OK | O6: =_xlfn.XLOOKUP(B6,'01_Raw_ATMs'!A:A,'01_Raw_ATMs'!A:A,"Not Found") -> ATM025 | P6: =IF(B6="","Missing ATM_ID","Valid") -> Valid | R6: ,
A7: TXN000006 | B7: ATM073 | C7: 45966 | D7: 0.62013889 | E7: Withdrawal | F7: 2000 | G7: Successful | I7: =COUNTIF($A:$A,A7) -> 1 | J7: =IF(AND(TRIM(G7)="Failed",H7=""),"Problem","OK") -> OK | K7: =PROPER(TRIM(G7)) -> Successful | L7: =PROPER(TRIM(E7)) -> Withdrawal | M7: =IF(OR(E7="Withdrawal",E7="Cash Deposit"),IF(F7>0,"OK","Problem"),IF(F7=0,"OK","Problem")) -> OK | N7: =IF(AND(C7>=DATE(2025,1,1),C7<=DATE(2026,6,30)),"OK","Problem") -> OK | O7: =_xlfn.XLOOKUP(B7,'01_Raw_ATMs'!A:A,'01_Raw_ATMs'!A:A,"Not Found") -> ATM073 | P7: =IF(B7="","Missing ATM_ID","Valid") -> Valid | R7: =COUNTIF(K2:K10001,"Successful") -> 9405
A8: TXN000007 | B8: ATM075 | C8: 45987 | D8: 0.64494213 | E8: Withdrawal | F8: 5000 | G8: Successful | I8: =COUNTIF($A:$A,A8) -> 1 | J8: =IF(AND(TRIM(G8)="Failed",H8=""),"Problem","OK") -> OK | K8: =PROPER(TRIM(G8)) -> Successful | L8: =PROPER(TRIM(E8)) -> Withdrawal | M8: =IF(OR(E8="Withdrawal",E8="Cash Deposit"),IF(F8>0,"OK","Problem"),IF(F8=0,"OK","Problem")) -> OK | N8: =IF(AND(C8>=DATE(2025,1,1),C8<=DATE(2026,6,30)),"OK","Problem") -> OK | O8: =_xlfn.XLOOKUP(B8,'01_Raw_ATMs'!A:A,'01_Raw_ATMs'!A:A,"Not Found") -> ATM075 | P8: =IF(B8="","Missing ATM_ID","Valid") -> Valid | R8: =COUNTIF(K2:K10001,"Failed") -> 595
A9: TXN000008 | B9: ATM095 | C9: 45831 | D9: 0.76287037 | E9: Withdrawal | F9: 8000 | G9: Successful | I9: =COUNTIF($A:$A,A9) -> 1 | J9: =IF(AND(TRIM(G9)="Failed",H9=""),"Problem","OK") -> OK | K9: =PROPER(TRIM(G9)) -> Successful | L9: =PROPER(TRIM(E9)) -> Withdrawal | M9: =IF(OR(E9="Withdrawal",E9="Cash Deposit"),IF(F9>0,"OK","Problem"),IF(F9=0,"OK","Problem")) -> OK | N9: =IF(AND(C9>=DATE(2025,1,1),C9<=DATE(2026,6,30)),"OK","Problem") -> OK | O9: =_xlfn.XLOOKUP(B9,'01_Raw_ATMs'!A:A,'01_Raw_ATMs'!A:A,"Not Found") -> ATM095 | P9: =IF(B9="","Missing ATM_ID","Valid") -> Valid | R9: =COUNTA(L2:L10001) -> 10000
A10: TXN000009 | B10: ATM097 | C10: 45898 | D10: 0.7603125 | E10: Withdrawal | F10: 500 | G10: Successful | I10: =COUNTIF($A:$A,A10) -> 1 | J10: =IF(AND(TRIM(G10)="Failed",H10=""),"Problem","OK") -> OK | K10: =PROPER(TRIM(G10)) -> Successful | L10: =PROPER(TRIM(E10)) -> Withdrawal | M10: =IF(OR(E10="Withdrawal",E10="Cash Deposit"),IF(F10>0,"OK","Problem"),IF(F10=0,"OK","Problem")) -> OK | N10: =IF(AND(C10>=DATE(2025,1,1),C10<=DATE(2026,6,30)),"OK","Problem") -> OK | O10: =_xlfn.XLOOKUP(B10,'01_Raw_ATMs'!A:A,'01_Raw_ATMs'!A:A,"Not Found") -> ATM097 | P10: =IF(B10="","Missing ATM_ID","Valid") -> Valid | R10: =COUNTBLANK(C2:C10001) -> 0
A11: TXN000010 | B11: ATM061 | C11: 45732 | D11: 0.66435185 | E11: Withdrawal | F11: 4000 | G11: Successful | I11: =COUNTIF($A:$A,A11) -> 1 | J11: =IF(AND(TRIM(G11)="Failed",H11=""),"Problem","OK") -> OK | K11: =PROPER(TRIM(G11)) -> Successful | L11: =PROPER(TRIM(E11)) -> Withdrawal | M11: =IF(OR(E11="Withdrawal",E11="Cash Deposit"),IF(F11>0,"OK","Problem"),IF(F11=0,"OK","Problem")) -> OK | N11: =IF(AND(C11>=DATE(2025,1,1),C11<=DATE(2026,6,30)),"OK","Problem") -> OK | O11: =_xlfn.XLOOKUP(B11,'01_Raw_ATMs'!A:A,'01_Raw_ATMs'!A:A,"Not Found") -> ATM061 | P11: =IF(B11="","Missing ATM_ID","Valid") -> Valid | R11: =COUNTIF(N2:N10001,"Problem") -> 0
A12: TXN000011 | B12: ATM032 | C12: 45809 | D12: 0.75065972 | E12: Balance Inquiry | F12: 0 | G12: Successful | I12: =COUNTIF($A:$A,A12) -> 1 | J12: =IF(AND(TRIM(G12)="Failed",H12=""),"Problem","OK") -> OK | K12: =PROPER(TRIM(G12)) -> Successful | L12: =PROPER(TRIM(E12)) -> Balance Inquiry | M12: =IF(OR(E12="Withdrawal",E12="Cash Deposit"),IF(F12>0,"OK","Problem"),IF(F12=0,"OK","Problem")) -> OK | N12: =IF(AND(C12>=DATE(2025,1,1),C12<=DATE(2026,6,30)),"OK","Problem") -> OK | O12: =_xlfn.XLOOKUP(B12,'01_Raw_ATMs'!A:A,'01_Raw_ATMs'!A:A,"Not Found") -> ATM032 | P12: =IF(B12="","Missing ATM_ID","Valid") -> Valid | R12: =MAX(F2:F10001) -> 25000
A13: TXN000012 | B13: ATM014 | C13: 46093 | D13: 0.41092593 | E13: Withdrawal | F13: 500 | G13: Successful | I13: =COUNTIF($A:$A,A13) -> 1 | J13: =IF(AND(TRIM(G13)="Failed",H13=""),"Problem","OK") -> OK | K13: =PROPER(TRIM(G13)) -> Successful | L13: =PROPER(TRIM(E13)) -> Withdrawal | M13: =IF(OR(E13="Withdrawal",E13="Cash Deposit"),IF(F13>0,"OK","Problem"),IF(F13=0,"OK","Problem")) -> OK | N13: =IF(AND(C13>=DATE(2025,1,1),C13<=DATE(2026,6,30)),"OK","Problem") -> OK | O13: =_xlfn.XLOOKUP(B13,'01_Raw_ATMs'!A:A,'01_Raw_ATMs'!A:A,"Not Found") -> ATM014 | P13: =IF(B13="","Missing ATM_ID","Valid") -> Valid | R13: =MIN(F2:F10001) -> 0
A14: TXN000013 | B14: ATM016 | C14: 46125 | D14: 0.31229167 | E14: Withdrawal | F14: 6000 | G14: Successful | I14: =COUNTIF($A:$A,A14) -> 1 | J14: =IF(AND(TRIM(G14)="Failed",H14=""),"Problem","OK") -> OK | K14: =PROPER(TRIM(G14)) -> Successful | L14: =PROPER(TRIM(E14)) -> Withdrawal | M14: =IF(OR(E14="Withdrawal",E14="Cash Deposit"),IF(F14>0,"OK","Problem"),IF(F14=0,"OK","Problem")) -> OK | N14: =IF(AND(C14>=DATE(2025,1,1),C14<=DATE(2026,6,30)),"OK","Problem") -> OK | O14: =_xlfn.XLOOKUP(B14,'01_Raw_ATMs'!A:A,'01_Raw_ATMs'!A:A,"Not Found") -> ATM016 | P14: =IF(B14="","Missing ATM_ID","Valid") -> Valid | R14: =COUNTIF(O2:O10001,"Not Found") -> 0
A15: TXN000014 | B15: ATM097 | C15: 46111 | D15: 0.7409375 | E15: Withdrawal | F15: 6000 | G15: Successful | I15: =COUNTIF($A:$A,A15) -> 1 | J15: =IF(AND(TRIM(G15)="Failed",H15=""),"Problem","OK") -> OK | K15: =PROPER(TRIM(G15)) -> Successful | L15: =PROPER(TRIM(E15)) -> Withdrawal | M15: =IF(OR(E15="Withdrawal",E15="Cash Deposit"),IF(F15>0,"OK","Problem"),IF(F15=0,"OK","Problem")) -> OK | N15: =IF(AND(C15>=DATE(2025,1,1),C15<=DATE(2026,6,30)),"OK","Problem") -> OK | O15: =_xlfn.XLOOKUP(B15,'01_Raw_ATMs'!A:A,'01_Raw_ATMs'!A:A,"Not Found") -> ATM097 | P15: =IF(B15="","Missing ATM_ID","Valid") -> Valid | R15: =COUNTIF(P2:P10001,"Missing ATM_ID") -> 3
A16: TXN000015 | B16: ATM021 | C16: 46144 | D16: 0.65850694 | E16: Balance Inquiry | F16: 0 | G16: Successful | I16: =COUNTIF($A:$A,A16) -> 1 | J16: =IF(AND(TRIM(G16)="Failed",H16=""),"Problem","OK") -> OK | K16: =PROPER(TRIM(G16)) -> Successful | L16: =PROPER(TRIM(E16)) -> Balance Inquiry | M16: =IF(OR(E16="Withdrawal",E16="Cash Deposit"),IF(F16>0,"OK","Problem"),IF(F16=0,"OK","Problem")) -> OK | N16: =IF(AND(C16>=DATE(2025,1,1),C16<=DATE(2026,6,30)),"OK","Problem") -> OK | O16: =_xlfn.XLOOKUP(B16,'01_Raw_ATMs'!A:A,'01_Raw_ATMs'!A:A,"Not Found") -> ATM021 | P16: =IF(B16="","Missing ATM_ID","Valid") -> Valid | R16: =COUNTA(A:A)-1 -> 10000
A17: TXN000016 | B17: ATM100 | C17: 46191 | D17: 0.63561343 | E17: Withdrawal | F17: 2500 | G17: Successful | I17: =COUNTIF($A:$A,A17) -> 1 | J17: =IF(AND(TRIM(G17)="Failed",H17=""),"Problem","OK") -> OK | K17: =PROPER(TRIM(G17)) -> Successful | L17: =PROPER(TRIM(E17)) -> Withdrawal | M17: =IF(OR(E17="Withdrawal",E17="Cash Deposit"),IF(F17>0,"OK","Problem"),IF(F17=0,"OK","Problem")) -> OK | N17: =IF(AND(C17>=DATE(2025,1,1),C17<=DATE(2026,6,30)),"OK","Problem") -> OK | O17: =_xlfn.XLOOKUP(B17,'01_Raw_ATMs'!A:A,'01_Raw_ATMs'!A:A,"Not Found") -> ATM100 | P17: =IF(B17="","Missing ATM_ID","Valid") -> Valid
A18: TXN000017 | B18: ATM043 | C18: 45985 | D18: 0.83689815 | E18: Withdrawal | F18: 4000 | G18: Successful | I18: =COUNTIF($A:$A,A18) -> 1 | J18: =IF(AND(TRIM(G18)="Failed",H18=""),"Problem","OK") -> OK | K18: =PROPER(TRIM(G18)) -> Successful | L18: =PROPER(TRIM(E18)) -> Withdrawal | M18: =IF(OR(E18="Withdrawal",E18="Cash Deposit"),IF(F18>0,"OK","Problem"),IF(F18=0,"OK","Problem")) -> OK | N18: =IF(AND(C18>=DATE(2025,1,1),C18<=DATE(2026,6,30)),"OK","Problem") -> OK | O18: =_xlfn.XLOOKUP(B18,'01_Raw_ATMs'!A:A,'01_Raw_ATMs'!A:A,"Not Found") -> ATM043 | P18: =IF(B18="","Missing ATM_ID","Valid") -> Valid
A19: TXN000018 | B19: ATM091 | C19: 45877 | D19: 0.22663194 | E19: Withdrawal | F19: 4000 | G19: Successful | I19: =COUNTIF($A:$A,A19) -> 1 | J19: =IF(AND(TRIM(G19)="Failed",H19=""),"Problem","OK") -> OK | K19: =PROPER(TRIM(G19)) -> Successful | L19: =PROPER(TRIM(E19)) -> Withdrawal | M19: =IF(OR(E19="Withdrawal",E19="Cash Deposit"),IF(F19>0,"OK","Problem"),IF(F19=0,"OK","Problem")) -> OK | N19: =IF(AND(C19>=DATE(2025,1,1),C19<=DATE(2026,6,30)),"OK","Problem") -> OK | O19: =_xlfn.XLOOKUP(B19,'01_Raw_ATMs'!A:A,'01_Raw_ATMs'!A:A,"Not Found") -> ATM091 | P19: =IF(B19="","Missing ATM_ID","Valid") -> Valid
A20: TXN000019 | B20: ATM054 | C20: 46056 | D20: 0.9012037 | E20: Withdrawal | F20: 8000 | G20: Successful | I20: =COUNTIF($A:$A,A20) -> 1 | J20: =IF(AND(TRIM(G20)="Failed",H20=""),"Problem","OK") -> OK | K20: =PROPER(TRIM(G20)) -> Successful | L20: =PROPER(TRIM(E20)) -> Withdrawal | M20: =IF(OR(E20="Withdrawal",E20="Cash Deposit"),IF(F20>0,"OK","Problem"),IF(F20=0,"OK","Problem")) -> OK | N20: =IF(AND(C20>=DATE(2025,1,1),C20<=DATE(2026,6,30)),"OK","Problem") -> OK | O20: =_xlfn.XLOOKUP(B20,'01_Raw_ATMs'!A:A,'01_Raw_ATMs'!A:A,"Not Found") -> ATM054 | P20: =IF(B20="","Missing ATM_ID","Valid") -> Valid
A21: TXN000020 | B21: ATM001 | C21: 46018 | D21: 0.475625 | E21: Mini Statement | F21: 0 | G21: Successful | I21: =COUNTIF($A:$A,A21) -> 1 | J21: =IF(AND(TRIM(G21)="Failed",H21=""),"Problem","OK") -> OK | K21: =PROPER(TRIM(G21)) -> Successful | L21: =PROPER(TRIM(E21)) -> Mini Statement | M21: =IF(OR(E21="Withdrawal",E21="Cash Deposit"),IF(F21>0,"OK","Problem"),IF(F21=0,"OK","Problem")) -> OK | N21: =IF(AND(C21>=DATE(2025,1,1),C21<=DATE(2026,6,30)),"OK","Problem") -> OK | O21: =_xlfn.XLOOKUP(B21,'01_Raw_ATMs'!A:A,'01_Raw_ATMs'!A:A,"Not Found") -> ATM001 | P21: =IF(B21="","Missing ATM_ID","Valid") -> Valid
A22: TXN000021 | B22: ATM069 | C22: 45883 | D22: 0.63711806 | E22: Withdrawal | F22: 4000 | G22: Successful | I22: =COUNTIF($A:$A,A22) -> 1 | J22: =IF(AND(TRIM(G22)="Failed",H22=""),"Problem","OK") -> OK | K22: =PROPER(TRIM(G22)) -> Successful | L22: =PROPER(TRIM(E22)) -> Withdrawal | M22: =IF(OR(E22="Withdrawal",E22="Cash Deposit"),IF(F22>0,"OK","Problem"),IF(F22=0,"OK","Problem")) -> OK | N22: =IF(AND(C22>=DATE(2025,1,1),C22<=DATE(2026,6,30)),"OK","Problem") -> OK | O22: =_xlfn.XLOOKUP(B22,'01_Raw_ATMs'!A:A,'01_Raw_ATMs'!A:A,"Not Found") -> ATM069 | P22: =IF(B22="","Missing ATM_ID","Valid") -> Valid
A23: TXN000022 | B23: ATM087 | C23: 46072 | D23: 0.7871412 | E23: Mini Statement | F23: 0 | G23: Failed | I23: =COUNTIF($A:$A,A23) -> 1 | J23: =IF(AND(TRIM(G23)="Failed",H23=""),"Problem","OK") -> Problem | K23: =PROPER(TRIM(G23)) -> Failed | L23: =PROPER(TRIM(E23)) -> Mini Statement | M23: =IF(OR(E23="Withdrawal",E23="Cash Deposit"),IF(F23>0,"OK","Problem"),IF(F23=0,"OK","Problem")) -> OK | N23: =IF(AND(C23>=DATE(2025,1,1),C23<=DATE(2026,6,30)),"OK","Problem") -> OK | O23: =_xlfn.XLOOKUP(B23,'01_Raw_ATMs'!A:A,'01_Raw_ATMs'!A:A,"Not Found") -> ATM087 | P23: =IF(B23="","Missing ATM_ID","Valid") -> Valid
A24: TXN000023 | B24: ATM004 | C24: 46061 | D24: 0.73751157 | E24: Withdrawal | F24: 4000 | G24: Successful | I24: =COUNTIF($A:$A,A24) -> 1 | J24: =IF(AND(TRIM(G24)="Failed",H24=""),"Problem","OK") -> OK | K24: =PROPER(TRIM(G24)) -> Successful | L24: =PROPER(TRIM(E24)) -> Withdrawal | M24: =IF(OR(E24="Withdrawal",E24="Cash Deposit"),IF(F24>0,"OK","Problem"),IF(F24=0,"OK","Problem")) -> OK | N24: =IF(AND(C24>=DATE(2025,1,1),C24<=DATE(2026,6,30)),"OK","Problem") -> OK | O24: =_xlfn.XLOOKUP(B24,'01_Raw_ATMs'!A:A,'01_Raw_ATMs'!A:A,"Not Found") -> ATM004 | P24: =IF(B24="","Missing ATM_ID","Valid") -> Valid
A25: TXN000024 | B25: ATM060 | C25: 45844 | D25: 0.18356481 | E25: Withdrawal | F25: 3000 | G25: Successful | I25: =COUNTIF($A:$A,A25) -> 1 | J25: =IF(AND(TRIM(G25)="Failed",H25=""),"Problem","OK") -> OK | K25: =PROPER(TRIM(G25)) -> Successful | L25: =PROPER(TRIM(E25)) -> Withdrawal | M25: =IF(OR(E25="Withdrawal",E25="Cash Deposit"),IF(F25>0,"OK","Problem"),IF(F25=0,"OK","Problem")) -> OK | N25: =IF(AND(C25>=DATE(2025,1,1),C25<=DATE(2026,6,30)),"OK","Problem") -> OK | O25: =_xlfn.XLOOKUP(B25,'01_Raw_ATMs'!A:A,'01_Raw_ATMs'!A:A,"Not Found") -> ATM060 | P25: =IF(B25="","Missing ATM_ID","Valid") -> Valid
A26: TXN000025 | B26: ATM049 | C26: 45942 | D26: 0.78710648 | E26: Withdrawal | F26: 1000 | G26: Successful | I26: =COUNTIF($A:$A,A26) -> 1 | J26: =IF(AND(TRIM(G26)="Failed",H26=""),"Problem","OK") -> OK | K26: =PROPER(TRIM(G26)) -> Successful | L26: =PROPER(TRIM(E26)) -> Withdrawal | M26: =IF(OR(E26="Withdrawal",E26="Cash Deposit"),IF(F26>0,"OK","Problem"),IF(F26=0,"OK","Problem")) -> OK | N26: =IF(AND(C26>=DATE(2025,1,1),C26<=DATE(2026,6,30)),"OK","Problem") -> OK | O26: =_xlfn.XLOOKUP(B26,'01_Raw_ATMs'!A:A,'01_Raw_ATMs'!A:A,"Not Found") -> ATM049 | P26: =IF(B26="","Missing ATM_ID","Valid") -> Valid
A27: TXN000026 | B27: ATM096 | C27: 45711 | D27: 0.97377315 | E27: Withdrawal | F27: 10000 | G27: Successful | I27: =COUNTIF($A:$A,A27) -> 1 | J27: =IF(AND(TRIM(G27)="Failed",H27=""),"Problem","OK") -> OK | K27: =PROPER(TRIM(G27)) -> Successful | L27: =PROPER(TRIM(E27)) -> Withdrawal | M27: =IF(OR(E27="Withdrawal",E27="Cash Deposit"),IF(F27>0,"OK","Problem"),IF(F27=0,"OK","Problem")) -> OK | N27: =IF(AND(C27>=DATE(2025,1,1),C27<=DATE(2026,6,30)),"OK","Problem") -> OK | O27: =_xlfn.XLOOKUP(B27,'01_Raw_ATMs'!A:A,'01_Raw_ATMs'!A:A,"Not Found") -> ATM096 | P27: =IF(B27="","Missing ATM_ID","Valid") -> Valid
A28: TXN000027 | B28: ATM004 | C28: 45911 | D28: 0.33447917 | E28: Withdrawal | F28: 1500 | G28: Successful | I28: =COUNTIF($A:$A,A28) -> 1 | J28: =IF(AND(TRIM(G28)="Failed",H28=""),"Problem","OK") -> OK | K28: =PROPER(TRIM(G28)) -> Successful | L28: =PROPER(TRIM(E28)) -> Withdrawal | M28: =IF(OR(E28="Withdrawal",E28="Cash Deposit"),IF(F28>0,"OK","Problem"),IF(F28=0,"OK","Problem")) -> OK | N28: =IF(AND(C28>=DATE(2025,1,1),C28<=DATE(2026,6,30)),"OK","Problem") -> OK | O28: =_xlfn.XLOOKUP(B28,'01_Raw_ATMs'!A:A,'01_Raw_ATMs'!A:A,"Not Found") -> ATM004 | P28: =IF(B28="","Missing ATM_ID","Valid") -> Valid
... A451: TXN000450 | B451: ATM098 | C451: 46186 | D451: 0.86947917 | E451: Withdrawal | F451: 1500 | G451: Successful | I451: =COUNTIF($A:$A,A451) -> 1 | J451: =IF(AND(TRIM(G451)="Failed",H451=""),"Problem","OK") -> OK | K451: =PROPER(TRIM(G451)) -> Successful | L451: =PROPER(TRIM(E451)) -> Withdrawal | M451: =IF(OR(E451="Withdrawal",E451="Cash Deposit"),IF(F451>0,"OK","Problem"),IF(F451=0,"OK","Problem")) -> OK | N451: =IF(AND(C451>=DATE(2025,1,1),C451<=DATE(2026,6,30)),"OK","Problem") -> OK | O451: =_xlfn.XLOOKUP(B451,'01_Raw_ATMs'!A:A,'01_Raw_ATMs'!A:A,"Not Found") -> ATM098 | P451: =IF(B451="","Missing ATM_ID","Valid") -> Valid
A452: TXN000451 | C452: 46176 | D452: 0.61798611 | E452: Withdrawal | F452: 8000 | G452: Successful | I452: =COUNTIF($A:$A,A452) -> 1 | J452: =IF(AND(TRIM(G452)="Failed",H452=""),"Problem","OK") -> OK | K452: =PROPER(TRIM(G452)) -> Successful | L452: =PROPER(TRIM(E452)) -> Withdrawal | M452: =IF(OR(E452="Withdrawal",E452="Cash Deposit"),IF(F452>0,"OK","Problem"),IF(F452=0,"OK","Problem")) -> OK | N452: =IF(AND(C452>=DATE(2025,1,1),C452<=DATE(2026,6,30)),"OK","Problem") -> OK | O452: =_xlfn.XLOOKUP(B452,'01_Raw_ATMs'!A:A,'01_Raw_ATMs'!A:A,"Not Found") -> 0 | P452: =IF(B452="","Missing ATM_ID","Valid") -> Missing ATM_ID
A453: TXN000452 | B453: ATM025 | C453: 45863 | D453: 0.80210648 | E453: Withdrawal | F453: 3000 | G453: Successful | I453: =COUNTIF($A:$A,A453) -> 1 | J453: =IF(AND(TRIM(G453)="Failed",H453=""),"Problem","OK") -> OK | K453: =PROPER(TRIM(G453)) -> Successful | L453: =PROPER(TRIM(E453)) -> Withdrawal | M453: =IF(OR(E453="Withdrawal",E453="Cash Deposit"),IF(F453>0,"OK","Problem"),IF(F453=0,"OK","Problem")) -> OK | N453: =IF(AND(C453>=DATE(2025,1,1),C453<=DATE(2026,6,30)),"OK","Problem") -> OK | O453: =_xlfn.XLOOKUP(B453,'01_Raw_ATMs'!A:A,'01_Raw_ATMs'!A:A,"Not Found") -> ATM025 | P453: =IF(B453="","Missing ATM_ID","Valid") -> Valid
A454: TXN000453 | B454: ATM036 | C454: 46035 | D454: 0.81417824 | E454: Withdrawal | F454: 1000 | G454: Successful | I454: =COUNTIF($A:$A,A454) -> 1 | J454: =IF(AND(TRIM(G454)="Failed",H454=""),"Problem","OK") -> OK | K454: =PROPER(TRIM(G454)) -> Successful | L454: =PROPER(TRIM(E454)) -> Withdrawal | M454: =IF(OR(E454="Withdrawal",E454="Cash Deposit"),IF(F454>0,"OK","Problem"),IF(F454=0,"OK","Problem")) -> OK | N454: =IF(AND(C454>=DATE(2025,1,1),C454<=DATE(2026,6,30)),"OK","Problem") -> OK | O454: =_xlfn.XLOOKUP(B454,'01_Raw_ATMs'!A:A,'01_Raw_ATMs'!A:A,"Not Found") -> ATM036 | P454: =IF(B454="","Missing ATM_ID","Valid") -> Valid
A455: TXN000454 | B455: ATM031 | C455: 46039 | D455: 0.64457176 | E455: Cash Deposit | F455: 10000 | G455: Successful | I455: =COUNTIF($A:$A,A455) -> 1 | J455: =IF(AND(TRIM(G455)="Failed",H455=""),"Problem","OK") -> OK | K455: =PROPER(TRIM(G455)) -> Successful | L455: =PROPER(TRIM(E455)) -> Cash Deposit | M455: =IF(OR(E455="Withdrawal",E455="Cash Deposit"),IF(F455>0,"OK","Problem"),IF(F455=0,"OK","Problem")) -> OK | N455: =IF(AND(C455>=DATE(2025,1,1),C455<=DATE(2026,6,30)),"OK","Problem") -> OK | O455: =_xlfn.XLOOKUP(B455,'01_Raw_ATMs'!A:A,'01_Raw_ATMs'!A:A,"Not Found") -> ATM031 | P455: =IF(B455="","Missing ATM_ID","Valid") -> Valid
A456: TXN000455 | B456: ATM045 | C456: 46010 | D456: 0.37310185 | E456: Balance Inquiry | F456: 0 | G456: Successful | I456: =COUNTIF($A:$A,A456) -> 1 | J456: =IF(AND(TRIM(G456)="Failed",H456=""),"Problem","OK") -> OK | K456: =PROPER(TRIM(G456)) -> Successful | L456: =PROPER(TRIM(E456)) -> Balance Inquiry | M456: =IF(OR(E456="Withdrawal",E456="Cash Deposit"),IF(F456>0,"OK","Problem"),IF(F456=0,"OK","Problem")) -> OK | N456: =IF(AND(C456>=DATE(2025,1,1),C456<=DATE(2026,6,30)),"OK","Problem") -> OK | O456: =_xlfn.XLOOKUP(B456,'01_Raw_ATMs'!A:A,'01_Raw_ATMs'!A:A,"Not Found") -> ATM045 | P456: =IF(B456="","Missing ATM_ID","Valid") -> Valid
A457: TXN000456 | B457: ATM037 | C457: 45686 | D457: 0.54923611 | E457: Withdrawal | F457: 2000 | G457: Successful | I457: =COUNTIF($A:$A,A457) -> 1 | J457: =IF(AND(TRIM(G457)="Failed",H457=""),"Problem","OK") -> OK | K457: =PROPER(TRIM(G457)) -> Successful | L457: =PROPER(TRIM(E457)) -> Withdrawal | M457: =IF(OR(E457="Withdrawal",E457="Cash Deposit"),IF(F457>0,"OK","Problem"),IF(F457=0,"OK","Problem")) -> OK | N457: =IF(AND(C457>=DATE(2025,1,1),C457<=DATE(2026,6,30)),"OK","Problem") -> OK | O457: =_xlfn.XLOOKUP(B457,'01_Raw_ATMs'!A:A,'01_Raw_ATMs'!A:A,"Not Found") -> ATM037 | P457: =IF(B457="","Missing ATM_ID","Valid") -> Valid
A458: TXN000457 | B458: ATM083 | C458: 45888 | D458: 0.76228009 | E458: Withdrawal | F458: 500 | G458: Successful | I458: =COUNTIF($A:$A,A458) -> 1 | J458: =IF(AND(TRIM(G458)="Failed",H458=""),"Problem","OK") -> OK | K458: =PROPER(TRIM(G458)) -> Successful | L458: =PROPER(TRIM(E458)) -> Withdrawal | M458: =IF(OR(E458="Withdrawal",E458="Cash Deposit"),IF(F458>0,"OK","Problem"),IF(F458=0,"OK","Problem")) -> OK | N458: =IF(AND(C458>=DATE(2025,1,1),C458<=DATE(2026,6,30)),"OK","Problem") -> OK | O458: =_xlfn.XLOOKUP(B458,'01_Raw_ATMs'!A:A,'01_Raw_ATMs'!A:A,"Not Found") -> ATM083 | P458: =IF(B458="","Missing ATM_ID","Valid") -> Valid
A459: TXN000458 | B459: ATM099 | C459: 45667 | D459: 0.63103009 | E459: Withdrawal | F459: 500 | G459: Successful | I459: =COUNTIF($A:$A,A459) -> 1 | J459: =IF(AND(TRIM(G459)="Failed",H459=""),"Problem","OK") -> OK | K459: =PROPER(TRIM(G459)) -> Successful | L459: =PROPER(TRIM(E459)) -> Withdrawal | M459: =IF(OR(E459="Withdrawal",E459="Cash Deposit"),IF(F459>0,"OK","Problem"),IF(F459=0,"OK","Problem")) -> OK | N459: =IF(AND(C459>=DATE(2025,1,1),C459<=DATE(2026,6,30)),"OK","Problem") -> OK | O459: =_xlfn.XLOOKUP(B459,'01_Raw_ATMs'!A:A,'01_Raw_ATMs'!A:A,"Not Found") -> ATM099 | P459: =IF(B459="","Missing ATM_ID","Valid") -> Valid
A460: TXN000459 | B460: ATM078 | C460: 45970 | D460: 0.78172454 | E460: Withdrawal | F460: 4000 | G460: Successful | I460: =COUNTIF($A:$A,A460) -> 1 | J460: =IF(AND(TRIM(G460)="Failed",H460=""),"Problem","OK") -> OK | K460: =PROPER(TRIM(G460)) -> Successful | L460: =PROPER(TRIM(E460)) -> Withdrawal | M460: =IF(OR(E460="Withdrawal",E460="Cash Deposit"),IF(F460>0,"OK","Problem"),IF(F460=0,"OK","Problem")) -> OK | N460: =IF(AND(C460>=DATE(2025,1,1),C460<=DATE(2026,6,30)),"OK","Problem") -> OK | O460: =_xlfn.XLOOKUP(B460,'01_Raw_ATMs'!A:A,'01_Raw_ATMs'!A:A,"Not Found") -> ATM078 | P460: =IF(B460="","Missing ATM_ID","Valid") -> Valid
A461: TXN000460 | B461: ATM059 | C461: 45916 | D461: 0.38869213 | E461: Withdrawal | F461: 8000 | G461: Successful | I461: =COUNTIF($A:$A,A461) -> 1 | J461: =IF(AND(TRIM(G461)="Failed",H461=""),"Problem","OK") -> OK | K461: =PROPER(TRIM(G461)) -> Successful | L461: =PROPER(TRIM(E461)) -> Withdrawal | M461: =IF(OR(E461="Withdrawal",E461="Cash Deposit"),IF(F461>0,"OK","Problem"),IF(F461=0,"OK","Problem")) -> OK | N461: =IF(AND(C461>=DATE(2025,1,1),C461<=DATE(2026,6,30)),"OK","Problem") -> OK | O461: =_xlfn.XLOOKUP(B461,'01_Raw_ATMs'!A:A,'01_Raw_ATMs'!A:A,"Not Found") -> ATM059 | P461: =IF(B461="","Missing ATM_ID","Valid") -> Valid
A462: TXN000461 | B462: ATM014 | C462: 45665 | D462: 0.69644676 | E462: Balance Inquiry | F462: 0 | G462: Successful | I462: =COUNTIF($A:$A,A462) -> 1 | J462: =IF(AND(TRIM(G462)="Failed",H462=""),"Problem","OK") -> OK | K462: =PROPER(TRIM(G462)) -> Successful | L462: =PROPER(TRIM(E462)) -> Balance Inquiry | M462: =IF(OR(E462="Withdrawal",E462="Cash Deposit"),IF(F462>0,"OK","Problem"),IF(F462=0,"OK","Problem")) -> OK | N462: =IF(AND(C462>=DATE(2025,1,1),C462<=DATE(2026,6,30)),"OK","Problem") -> OK | O462: =_xlfn.XLOOKUP(B462,'01_Raw_ATMs'!A:A,'01_Raw_ATMs'!A:A,"Not Found") -> ATM014 | P462: =IF(B462="","Missing ATM_ID","Valid") -> Valid
...

Sheet 05_Cleaned_Transactions
A1: Transaction_ID | B1: ATM_ID | C1: Transaction_Date | D1: Transaction_Time | E1: Clean_Transaction_Type | F1: Amount | G1: Clean_Status | H1: Failure_Reason
A2: TXN000001 | B2: ATM094 | C2: 45979 | D2: 0.60563657 | E2: Withdrawal | F2: 8000 | G2: Successful
A3: TXN000002 | B3: ATM006 | C3: 46104 | D3: 0.0415625 | E3: Withdrawal | F3: 10000 | G3: Successful
A4: TXN000003 | B4: ATM056 | C4: 45729 | D4: 0.9571875 | E4: Withdrawal | F4: 10000 | G4: Successful
A5: TXN000004 | B5: ATM093 | C5: 45965 | D5: 0.69613426 | E5: Withdrawal | F5: 2500 | G5: Successful
A6: TXN000005 | B6: ATM025 | C6: 46088 | D6: 0.76716435 | E6: Balance Inquiry | F6: 0 | G6: Successful
A7: TXN000006 | B7: ATM073 | C7: 45966 | D7: 0.62013889 | E7: Withdrawal | F7: 2000 | G7: Successful
A8: TXN000007 | B8: ATM075 | C8: 45987 | D8: 0.64494213 | E8: Withdrawal | F8: 5000 | G8: Successful
A9: TXN000008 | B9: ATM095 | C9: 45831 | D9: 0.76287037 | E9: Withdrawal | F9: 8000 | G9: Successful
A10: TXN000009 | B10: ATM097 | C10: 45898 | D10: 0.7603125 | E10: Withdrawal | F10: 500 | G10: Successful
A11: TXN000010 | B11: ATM061 | C11: 45732 | D11: 0.66435185 | E11: Withdrawal | F11: 4000 | G11: Successful
A12: TXN000011 | B12: ATM032 | C12: 45809 | D12: 0.75065972 | E12: Balance Inquiry | F12: 0 | G12: Successful
A13: TXN000012 | B13: ATM014 | C13: 46093 | D13: 0.41092593 | E13: Withdrawal | F13: 500 | G13: Successful
... A451: TXN000450 | B451: ATM098 | C451: 46186 | D451: 0.86947917 | E451: Withdrawal | F451: 1500 | G451: Successful
A452: TXN000451 | C452: 46176 | D452: 0.61798611 | E452: Withdrawal | F452: 8000 | G452: Successful
A453: TXN000452 | B453: ATM025 | C453: 45863 | D453: 0.80210648 | E453: Withdrawal | F453: 3000 | G453: Successful
A454: TXN000453 | B454: ATM036 | C454: 46035 | D454: 0.81417824 | E454: Withdrawal | F454: 1000 | G454: Successful
A455: TXN000454 | B455: ATM031 | C455: 46039 | D455: 0.64457176 | E455: Cash Deposit | F455: 10000 | G455: Successful
A456: TXN000455 | B456: ATM045 | C456: 46010 | D456: 0.37310185 | E456: Balance Inquiry | F456: 0 | G456: Successful
A457: TXN000456 | B457: ATM037 | C457: 45686 | D457: 0.54923611 | E457: Withdrawal | F457: 2000 | G457: Successful
A458: TXN000457 | B458: ATM083 | C458: 45888 | D458: 0.76228009 | E458: Withdrawal | F458: 500 | G458: Successful
A459: TXN000458 | B459: ATM099 | C459: 45667 | D459: 0.63103009 | E459: Withdrawal | F459: 500 | G459: Successful
A460: TXN000459 | B460: ATM078 | C460: 45970 | D460: 0.78172454 | E460: Withdrawal | F460: 4000 | G460: Successful
A461: TXN000460 | B461: ATM059 | C461: 45916 | D461: 0.38869213 | E461: Withdrawal | F461: 8000 | G461: Successful
A462: TXN000461 | B462: ATM014 | C462: 45665 | D462: 0.69644676 | E462: Balance Inquiry | F462: 0 | G462: Successful
A463: TXN000462 | B463: ATM077 | C463: 45947 | D463: 0.46284722 | E463: Withdrawal | F463: 2500 | G463: Successful
A464: TXN000463 | B464: ATM036 | C464: 45925 | D464: 0.79005787 | E464: Withdrawal | F464: 1500 | G464: Successful
... A886: TXN000885 | B886: ATM039 | C886: 45793 | D886: 0.84664352 | E886: Balance Inquiry | F886: 0 | G886: Successful
A887: TXN000886 | B887: ATM048 | C887: 45953 | D887: 0.79385417 | E887: Withdrawal | F887: 5000 | G887: Failed | H887: Timeout
A888: TXN000887 | B888: ATM021 | C888: 45950 | D888: 0.34158565 | E888: Withdrawal | F888: 10000 | G888: Successful
A889: TXN000888 | B889: ATM021 | C889: 45901 | D889: 0.30597222 | E889: Withdrawal | F889: 2500 | G889: Successful
A890: TXN000889 | B890: ATM027 | C890: 45693 | D890: 0.76538194 | E890: Withdrawal | F890: 6000 | G890: Failed | H890: Timeout
A891: TXN000890 | B891: ATM039 | C891: 45782 | D891: 0.89304398 | E891: Withdrawal | F891: 1500 | G891: Failed | H891: Network Error
A892: TXN000891 | B892: ATM020 | C892: 45662 | D892: 0.94064815 | E892: Withdrawal | F892: 2500 | G892: Successful
A893: TXN000892 | B893: ATM038 | C893: 45808 | D893: 0.82428241 | E893: Mini Statement | F893: 0 | G893: Successful
A894: TXN000893 | B894: ATM015 | C894: 46148 | D894: 0.83938657 | E894: Withdrawal | F894: 2500 | G894: Successful
A895: TXN000894 | B895: ATM080 | C895: 45883 | D895: 0.6287037 | E895: Withdrawal | F895: 10000 | G895: Successful
A896: TXN000895 | B896: ATM068 | C896: 45885 | D896: 0.8258912 | E896: Withdrawal | F896: 1000 | G896: Successful
A897: TXN000896 | B897: ATM058 | C897: 45747 | D897: 0.93416667 | E897: Withdrawal | F897: 8000 | G897: Successful
A898: TXN000897 | B898: ATM008 | C898: 46027 | D898: 0.57354167 | E898: Withdrawal | F898: 4000 | G898: Successful
...

Sheet 03_Raw_Cash_Refills
A1: Refill_ID | B1: ATM_ID | C1: Refill_Date | D1: Refill_Amount
A2: REF00001 | B2: ATM001 | C2: 45662 | D2: 125000
A3: REF00002 | B3: ATM001 | C3: 45675 | D3: 100000
A4: REF00003 | B4: ATM001 | C4: 45692 | D4: 50000
A5: REF00004 | B5: ATM001 | C5: 45709 | D5: 100000
A6: REF00005 | B6: ATM001 | C6: 45722 | D6: 100000
A7: REF00006 | B7: ATM001 | C7: 45734 | D7: 75000
A8: REF00007 | B8: ATM001 | C8: 45745 | D8: 50000
A9: REF00008 | B9: ATM001 | C9: 45752 | D9: 75000
A10: REF00009 | B10: ATM001 | C10: 45765 | D10: 200000
A11: REF00010 | B11: ATM001 | C11: 45779 | D11: 50000
A12: REF00011 | B12: ATM001 | C12: 45792 | D12: 50000
A13: REF00012 | B13: ATM001 | C13: 45806 | D13: 75000
... A21: REF00020 | B21: ATM001 | C21: 45928 | D21: 200000
A22: REF00021 | B22: ATM001 | C22: 45941
A23: REF00022 | B23: ATM001 | C23: 45949 | D23: 150000
A24: REF00023 | B24: ATM001 | C24: 45962 | D24: 150000
A25: REF00024 | B25: ATM001 | C25: 45977 | D25: 50000
A26: REF00025 | B26: ATM001 | C26: 45988 | D26: 200000
A27: REF00026 | B27: ATM001 | C27: 45997 | D27: 200000
A28: REF00027 | B28: ATM001 | C28: 46005 | D28: 150000
A29: REF00028 | B29: ATM001 | C29: 46017 | D29: 150000
A30: REF00029 | B30: ATM001 | C30: 46026 | D30: 150000
A31: REF00030 | B31: ATM001 | C31: 46036 | D31: 50000
A32: REF00031 | B32: ATM001 | C32: 46043 | D32: 100000
A33: REF00032 | B33: ATM001 | C33: 46060 | D33: 100000
A34: REF00033 | B34: ATM001 | C34: 46076 | D34: 75000
... A251: REF00250 | B251: ATM006 | C251: 46149 | D251: 125000
A252: REF00251 | B252: ATM006 | C252: 46160
A253: REF00252 | B253: ATM006 | C253: 46174 | D253: 75000
A254: REF00253 | B254: ATM006 | C254: 46185 | D254: 150000
A255: REF00254 | B255: ATM006 | C255: 46192 | D255: 200000
A256: REF00255 | B256: ATM006 | C256: 46200 | D256: 150000
A257: REF00256 | B257: ATM007 | C257: 45681 | D257: 150000
A258: REF00257 | B258: ATM007 | C258: 45697 | D258: 125000
A259: REF00258 | B259: ATM007 | C259: 45705 | D259: 125000
A260: REF00259 | B260: ATM007 | C260: 45721 | D260: 50000
A261: REF00260 | B261: ATM007 | C261: 45736 | D261: 100000
A262: REF00261 | B262: ATM007 | C262: 45751 | D262: 50000
A263: REF00262 | B263: ATM007 | C263: 45763 | D263: 200000
...

Sheet 04_Raw_Maintenance
A1: Maintenance_ID | B1: ATM_ID | C1: Maintenance_Date | D1: Issue_Type | E1: Downtime_Hours
A2: MAIN00001 | B2: ATM001 | C2: 46043 | D2: Printer | E2: 11.8
A3: MAIN00002 | B3: ATM001 | C3: 45845 | D3: Screen | E3: 11
A4: MAIN00003 | B4: ATM001 | C4: 45899 | D4: Network | E4: 2.5
A5: MAIN00004 | B5: ATM001 | C5: 45969 | D5: Card Reader | E5: 2.9
A6: MAIN00005 | B6: ATM001 | C6: 45847 | D6: Printer | E6: 10.6
A7: MAIN00006 | B7: ATM002 | C7: 45669 | D7: Cash Dispenser | E7: 4.3
A8: MAIN00007 | B8: ATM002 | C8: 46015 | D8: Cash Dispenser | E8: 9.7
A9: MAIN00008 | B9: ATM002 | C9: 46061 | D9: Card Reader | E9: 6
A10: MAIN00009 | B10: ATM002 | C10: 45838 | D10: Network | E10: 6.6
A11: MAIN00010 | B11: ATM002 | C11: 46070 | D11: Cash Dispenser | E11: 6.3
A12: MAIN00011 | B12: ATM002 | C12: 45758 | D12: Cash Dispenser | E12: 7.7
A13: MAIN00012 | B13: ATM003 | C13: 45937 | D13: Software | E13: 6.3
... A515: MAIN00514 | B515: ATM100 | C515: 46066 | D515: Screen | E515: 8.4

Sheet 05_Project_Guide
A1: Step | B1: What We Will Do | C1: Tool
A2: 1 | B2: Understand business problem and KPIs | C2: Concept
A3: 2 | B3: Understand tables and relationships | C3: Concept
A4: 3 | B4: Inspect and clean raw data | C4: Excel
A5: 4 | B5: Load cleaned data into relational database | C5: PostgreSQL
A6: 5 | B6: Analyze KPIs using SQL | C6: PostgreSQL
A7: 6 | B7: Perform deeper EDA and anomaly analysis | C7: Python / Pandas
A8: 7 | B8: Build data model and calculations | C8: Power BI / DAX
A9: 8 | B9: Create management dashboard | C9: Power BI
A10: 9 | B10: Write insights and recommendations | C10: Business Analysis
A11: 10 | B11: Prepare GitHub README and resume bullets | C11: GitHub / Resume
